                  #  Try and exception handling in python
#
# a=int(input("Enter your first number\n"))
# b=int(input("Enter your second number\n"))
# try:
#     print(a+str(b))
# except Exception as s:
#     print(s)
# print(a+b)

# a=int(input("Enter your first number"))
# b=int(input("Enter your second number"))
# try:
#     print(a+(b))
# except Exception as d:
#     print(d)
# print(a-b)

#------------------------try and except -------------------------------------
#
# inp1=input("enter your first number\n")
# inp2=input("enter your second number\n")
# try:
#     print(f"addition of inp1 and inp2:",{str(inp1)}+{inp2})
# except Exception as store:
#     print(store)
# print("addition of inp1 and inp2:",int(inp1)+int(inp2))

# print("I want to enter the out of 100 number")
# inp1=input("enter for try and continue the command\n")
# while True:
#     if inp1=="try":
#         try:
#             # while 1:
#             inp = int(input("enter the  number\n"))
#             if inp > 100:
#                 print("congratulation you enter the out of 100 number")
#                 break
#             else:
#                 print("try again..")
#                 continue
#         except Exception as store:
#             print(store)
#             break
# while 1:
#     inp=int(input("enter the your number\n"))
#     if inp>100:
#         print("congratulation you enter the out of 100 number")
#         break
#     else:
#         print("try again..")
#     continue

inp1=input("Enter your first numbers \n")
inp2=input("Enter your second number \n")
# try:
#     print("Sum of these two numbers", inp1 + int(inp2))
# except Exception as e:
#     # print(e)
#     print("sum of these two numbers", int(inp1)+int(inp2))
